Workbook

Sheet Test Scenarios
A1: Service | B1: Test ID | C1: FR liên quan | D1: Quy tắc/NFR liên quan (BR-x / NFR-x — mã chính thức từ BA bản 1.2) | E1: Loại | F1: Kịch bản kiểm thử | G1: Điều kiện tiên quyết | H1: Các bước thực hiện | I1: Dữ liệu mẫu | J1: Kết quả mong đợi | K1: Ưu tiên | L1: Nhóm kiểm thử | M1: Nguồn kịch bản | N1: Dự kiến khi chạy | O1: Đối chiếu với BA (25 FR / 10 quy tắc nghiệp vụ)
A2: Customer Service | B2: TC-CUST-01 | C2: FR-01 | D2: — | E2: Positive | F2: Đăng ký tài khoản khách hàng thành công | G2: Email chưa tồn tại trong hệ thống | H2: 1. POST /customers/register với fullName, email, password hợp lệ 2. Kiểm tra response | I2: {fullName:'Nguyễn Văn A', email:'a@test.com', password:'123456'} | J2: 201 Created, trả về token JWT + object customer KHÔNG chứa passwordHash | K2: Cao | L2: Chức năng | M2: File cũ | N2: PASS (đã kiểm thử tự động) | O2: Đúng BA
A3: Customer Service | B3: TC-CUST-02 | C3: FR-01 | D3: — | E3: Negative | F3: Đăng ký với email đã tồn tại | G3: Email đã được đăng ký trước đó | H3: 1. Đăng ký lần 1 thành công 2. Đăng ký lần 2 với cùng email | I3: email trùng ở cả 2 lần | J3: 409 Conflict, error.code = EMAIL_TAKEN | K3: Cao | L3: Chức năng | M3: File cũ | N3: PASS (đã kiểm thử tự động) | O3: Đúng BA
A4: Customer Service | B4: TC-CUST-03 | C4: FR-01 | D4: — | E4: Negative | F4: Đăng ký thiếu trường bắt buộc | G4: Không có | H4: POST /customers/register thiếu field password | I4: {fullName:'A', email:'a@test.com'} (thiếu password) | J4: 400 Bad Request, error.code = INVALID_INPUT | K4: Trung bình | L4: Chức năng | M4: File cũ | N4: PASS (đã kiểm thử tự động) | O4: Đúng BA
A5: Customer Service | B5: TC-CUST-04 | C5: FR-01 | D5: — | E5: Positive | F5: Đăng nhập đúng thông tin | G5: Tài khoản đã tồn tại, đang active | H5: POST /customers/login với email/password đúng | I5: email + password đã đăng ký | J5: 200 OK, trả về token JWT mới | K5: Cao | L5: Chức năng | M5: File cũ | N5: PASS (đã kiểm thử tự động) | O5: Đúng BA
A6: Customer Service | B6: TC-CUST-05 | C6: FR-01 | D6: NFR-4a | E6: Negative | F6: Đăng nhập sai mật khẩu | G6: Tài khoản đã tồn tại | H6: POST /customers/login với password sai | I6: email đúng, password sai | J6: 401 Unauthorized, error.code = INVALID_CREDENTIALS | K6: Cao | L6: Chức năng | M6: File cũ | N6: PASS (đã kiểm thử tự động) | O6: Đúng BA
A7: Customer Service | B7: TC-CUST-06 | C7: FR-22 | D7: NFR-4a | E7: Negative | F7: Đăng nhập tài khoản đã bị khóa | G7: Tài khoản đã bị ops_admin disable (active=false) | H7: POST /customers/login với thông tin đúng của tài khoản đã khóa | I7: email/password đúng nhưng active=false | J7: 403 Forbidden, error.code = ACCOUNT_DISABLED | K7: Trung bình | L7: Chức năng | M7: File cũ | N7: PASS (đã kiểm thử tự động) | O7: Đúng BA
A8: Customer Service | B8: TC-CUST-07 | C8: FR-01 | D8: NFR-4a | E8: Negative | F8: Gọi API cần xác thực mà không có token | G8: Không có | H8: GET /customers/me không kèm Authorization header | I8: Không có token | J8: 401 Unauthorized, error.code = UNAUTHORIZED | K8: Cao | L8: Bảo mật | M8: File cũ | N8: PASS (đã kiểm thử tự động) | O8: Đúng BA
A9: Customer Service | B9: TC-CUST-08 | C9: FR-01 | D9: — | E9: Positive | F9: Cập nhật thông tin cá nhân | G9: Đã đăng nhập với token customer hợp lệ | H9: PUT /customers/me với fullName/phone mới | I9: {fullName:'Tên mới', phone:'0900000009'} | J9: 200 OK, dữ liệu trả về đã cập nhật đúng, updatedAt thay đổi | K9: Trung bình | L9: Chức năng | M9: File cũ | N9: PASS (đã kiểm thử tự động) | O9: Đúng BA
A10: Customer Service | B10: TC-CUST-09 | C10: FR-20 | D10: NFR-4a | E10: Negative | F10: Khách hàng cố tra cứu hồ sơ khách khác | G10: Đăng nhập bằng token role=customer | H10: GET /customers/{id} của khách hàng khác | I10: token role customer, id không phải chính mình | J10: 403 Forbidden (chỉ ops_staff/ops_admin được tra cứu theo id) | K10: Trung bình | L10: Bảo mật | M10: File cũ | N10: PASS (đã kiểm thử tự động) | O10: Đúng BA
A11: Customer Service | B11: TC-CUST-10 | C11: FR-20 | D11: — | E11: Positive | F11: Ops_staff xem danh sách toàn bộ khách hàng | G11: Có token role=ops_staff | H11: GET /customers/all | I11: token ops_staff | J11: 200 OK, trả về mảng toàn bộ khách hàng, không chứa passwordHash | K11: Trung bình | L11: Chức năng | M11: File cũ | N11: PASS (đã kiểm thử tự động) | O11: Đúng BA
A12: Customer Service | B12: TC-CUST-11 | C12: FR-22 | D12: BR-8, NFR-4a | E12: Negative | F12: ops_staff (không phải ops_admin) cố khóa tài khoản khách hàng bằng API trực tiếp | G12: Có khách hàng đang active; có token ops_staff | H12: 1. Đăng ký khách hàng 2. PATCH /customers/{id}/disable bằng token ops_staff 3. Đăng nhập lại bằng tài khoản đó | I12: token ops_staff, id khách vừa tạo | J12: Bước 2: 403 Forbidden. Bước 3: 200 OK (tài khoản vẫn active). Khác TC-ADM-03 ở chỗ gọi thẳng Customer Service, không đi qua Admin Service | K12: Cao | L12: Bảo mật | M12: TS-IDN-014 | N12: PASS | O12: Đúng BA
... A188: API Gateway | B188: TC-GATE-03 | C188: — | D188: NFR-2 | E188: Negative | F188: Spam API liên tục phải được giới hạn tần suất (rate limit) | G188: Không có | H188: Gửi 100 POST /trips song song cùng một token, kiểm tra có ít nhất 1 phản hồi 429, rồi gửi thêm 1 request nữa kiểm tra hệ thống vẫn phản hồi bình thường | I188: 1 khách, body đặt xe hợp lệ lặp lại 100 lần | J188: Có ít nhất 1 phản hồi 429 trong 100 request; request sau đó vẫn nhận 200/201/429, không phải 500 hoặc không phản hồi | K188: Trung bình | L188: Bảo mật | M188: Bảng chấm thực hành, mục 29 | N188: FAIL (đã xác nhận bằng test thật ngày 01/10/2026, testcase/tests/gateway/TC-GATE-03.test.js): 0/100 request bị giới hạn (rateLimitedCount=0) - hệ thống hiện chưa có middleware rate limit | O188: BA chưa quy định (yêu cầu riêng của bảng chấm thực hành, không thuộc phạm vi 25 FR/10 quy tắc của BA)

Sheet Tổng quan
A1: Service | B1: Tổng số test case | C1: Positive | D1: Negative | E1: Đã có (file cũ) | F1: Thêm mới | G1: Dự kiến FAIL | H1: Cần xác nhận | I1: Lệch BA | J1: BA chưa quy định
A2: Customer Service | B2: =COUNTIF('Test Scenarios'!$A$2:$A$188,$A2) -> 21 | C2: =COUNTIFS('Test Scenarios'!$A$2:$A$188,$A2,'Test Scenarios'!$E$2:$E$188,"Positive") -> 6 | D2: =COUNTIFS('Test Scenarios'!$A$2:$A$188,$A2,'Test Scenarios'!$E$2:$E$188,"Negative") -> 15 | E2: =COUNTIFS('Test Scenarios'!$A$2:$A$188,$A2,'Test Scenarios'!$M$2:$M$188,"File cũ") -> 10 | F2: =B2-E2 -> 11 | G2: =COUNTIFS('Test Scenarios'!$A$2:$A$188,$A2,'Test Scenarios'!$N$2:$N$188,"FAIL*") -> 3 | H2: =COUNTIFS('Test Scenarios'!$A$2:$A$188,$A2,'Test Scenarios'!$N$2:$N$188,"Cần xác nhận*") -> 1 | I2: =COUNTIFS('Test Scenarios'!$A$2:$A$188,$A2,'Test Scenarios'!$O$2:$O$188,"Lệch BA*") -> 2 | J2: =COUNTIFS('Test Scenarios'!$A$2:$A$188,$A2,'Test Scenarios'!$O$2:$O$188,"BA chưa quy định*") -> 1
A3: Driver Service | B3: =COUNTIF('Test Scenarios'!$A$2:$A$188,$A3) -> 20 | C3: =COUNTIFS('Test Scenarios'!$A$2:$A$188,$A3,'Test Scenarios'!$E$2:$E$188,"Positive") -> 10 | D3: =COUNTIFS('Test Scenarios'!$A$2:$A$188,$A3,'Test Scenarios'!$E$2:$E$188,"Negative") -> 10 | E3: =COUNTIFS('Test Scenarios'!$A$2:$A$188,$A3,'Test Scenarios'!$M$2:$M$188,"File cũ") -> 10 | F3: =B3-E3 -> 10 | G3: =COUNTIFS('Test Scenarios'!$A$2:$A$188,$A3,'Test Scenarios'!$N$2:$N$188,"FAIL*") -> 5 | H3: =COUNTIFS('Test Scenarios'!$A$2:$A$188,$A3,'Test Scenarios'!$N$2:$N$188,"Cần xác nhận*") -> 1 | I3: =COUNTIFS('Test Scenarios'!$A$2:$A$188,$A3,'Test Scenarios'!$O$2:$O$188,"Lệch BA*") -> 5 | J3: =COUNTIFS('Test Scenarios'!$A$2:$A$188,$A3,'Test Scenarios'!$O$2:$O$188,"BA chưa quy định*") -> 1
A4: Trip Service | B4: =COUNTIF('Test Scenarios'!$A$2:$A$188,$A4) -> 22 | C4: =COUNTIFS('Test Scenarios'!$A$2:$A$188,$A4,'Test Scenarios'!$E$2:$E$188,"Positive") -> 6 | D4: =COUNTIFS('Test Scenarios'!$A$2:$A$188,$A4,'Test Scenarios'!$E$2:$E$188,"Negative") -> 16 | E4: =COUNTIFS('Test Scenarios'!$A$2:$A$188,$A4,'Test Scenarios'!$M$2:$M$188,"File cũ") -> 12 | F4: =B4-E4 -> 10 | G4: =COUNTIFS('Test Scenarios'!$A$2:$A$188,$A4,'Test Scenarios'!$N$2:$N$188,"FAIL*") -> 6 | H4: =COUNTIFS('Test Scenarios'!$A$2:$A$188,$A4,'Test Scenarios'!$N$2:$N$188,"Cần xác nhận*") -> 0 | I4: =COUNTIFS('Test Scenarios'!$A$2:$A$188,$A4,'Test Scenarios'!$O$2:$O$188,"Lệch BA*") -> 2 | J4: =COUNTIFS('Test Scenarios'!$A$2:$A$188,$A4,'Test Scenarios'!$O$2:$O$188,"BA chưa quy định*") -> 6
A5: Dispatch Service | B5: =COUNTIF('Test Scenarios'!$A$2:$A$188,$A5) -> 20 | C5: =COUNTIFS('Test Scenarios'!$A$2:$A$188,$A5,'Test Scenarios'!$E$2:$E$188,"Positive") -> 8 | D5: =COUNTIFS('Test Scenarios'!$A$2:$A$188,$A5,'Test Scenarios'!$E$2:$E$188,"Negative") -> 12 | E5: =COUNTIFS('Test Scenarios'!$A$2:$A$188,$A5,'Test Scenarios'!$M$2:$M$188,"File cũ") -> 7 | F5: =B5-E5 -> 13 | G5: =COUNTIFS('Test Scenarios'!$A$2:$A$188,$A5,'Test Scenarios'!$N$2:$N$188,"FAIL*") -> 6 | H5: =COUNTIFS('Test Scenarios'!$A$2:$A$188,$A5,'Test Scenarios'!$N$2:$N$188,"Cần xác nhận*") -> 3 | I5: =COUNTIFS('Test Scenarios'!$A$2:$A$188,$A5,'Test Scenarios'!$O$2:$O$188,"Lệch BA*") -> 3 | J5: =COUNTIFS('Test Scenarios'!$A$2:$A$188,$A5,'Test Scenarios'!$O$2:$O$188,"BA chưa quy định*") -> 3
A6: Location Service | B6: =COUNTIF('Test Scenarios'!$A$2:$A$188,$A6) -> 21 | C6: =COUNTIFS('Test Scenarios'!$A$2:$A$188,$A6,'Test Scenarios'!$E$2:$E$188,"Positive") -> 12 | D6: =COUNTIFS('Test Scenarios'!$A$2:$A$188,$A6,'Test Scenarios'!$E$2:$E$188,"Negative") -> 9 | E6: =COUNTIFS('Test Scenarios'!$A$2:$A$188,$A6,'Test Scenarios'!$M$2:$M$188,"File cũ") -> 5 | F6: =B6-E6 -> 16 | G6: =COUNTIFS('Test Scenarios'!$A$2:$A$188,$A6,'Test Scenarios'!$N$2:$N$188,"FAIL*") -> 5 | H6: =COUNTIFS('Test Scenarios'!$A$2:$A$188,$A6,'Test Scenarios'!$N$2:$N$188,"Cần xác nhận*") -> 1 | I6: =COUNTIFS('Test Scenarios'!$A$2:$A$188,$A6,'Test Scenarios'!$O$2:$O$188,"Lệch BA*") -> 4 | J6: =COUNTIFS('Test Scenarios'!$A$2:$A$188,$A6,'Test Scenarios'!$O$2:$O$188,"BA chưa quy định*") -> 1
A7: Pricing Service | B7: =COUNTIF('Test Scenarios'!$A$2:$A$188,$A7) -> 20 | C7: =COUNTIFS('Test Scenarios'!$A$2:$A$188,$A7,'Test Scenarios'!$E$2:$E$188,"Positive") -> 10 | D7: =COUNTIFS('Test Scenarios'!$A$2:$A$188,$A7,'Test Scenarios'!$E$2:$E$188,"Negative") -> 10 | E7: =COUNTIFS('Test Scenarios'!$A$2:$A$188,$A7,'Test Scenarios'!$M$2:$M$188,"File cũ") -> 4 | F7: =B7-E7 -> 16 | G7: =COUNTIFS('Test Scenarios'!$A$2:$A$188,$A7,'Test Scenarios'!$N$2:$N$188,"FAIL*") -> 2 | H7: =COUNTIFS('Test Scenarios'!$A$2:$A$188,$A7,'Test Scenarios'!$N$2:$N$188,"Cần xác nhận*") -> 0 | I7: =COUNTIFS('Test Scenarios'!$A$2:$A$188,$A7,'Test Scenarios'!$O$2:$O$188,"Lệch BA*") -> 1 | J7: =COUNTIFS('Test Scenarios'!$A$2:$A$188,$A7,'Test Scenarios'!$O$2:$O$188,"BA chưa quy định*") -> 4
A8: Payment Service | B8: =COUNTIF('Test Scenarios'!$A$2:$A$188,$A8) -> 20 | C8: =COUNTIFS('Test Scenarios'!$A$2:$A$188,$A8,'Test Scenarios'!$E$2:$E$188,"Positive") -> 9 | D8: =COUNTIFS('Test Scenarios'!$A$2:$A$188,$A8,'Test Scenarios'!$E$2:$E$188,"Negative") -> 11 | E8: =COUNTIFS('Test Scenarios'!$A$2:$A$188,$A8,'Test Scenarios'!$M$2:$M$188,"File cũ") -> 8 | F8: =B8-E8 -> 12 | G8: =COUNTIFS('Test Scenarios'!$A$2:$A$188,$A8,'Test Scenarios'!$N$2:$N$188,"FAIL*") -> 4 | H8: =COUNTIFS('Test Scenarios'!$A$2:$A$188,$A8,'Test Scenarios'!$N$2:$N$188,"Cần xác nhận*") -> 4 | I8: =COUNTIFS('Test Scenarios'!$A$2:$A$188,$A8,'Test Scenarios'!$O$2:$O$188,"Lệch BA*") -> 3 | J8: =COUNTIFS('Test Scenarios'!$A$2:$A$188,$A8,'Test Scenarios'!$O$2:$O$188,"BA chưa quy định*") -> 2
A9: Notification Service | B9: =COUNTIF('Test Scenarios'!$A$2:$A$188,$A9) -> 20 | C9: =COUNTIFS('Test Scenarios'!$A$2:$A$188,$A9,'Test Scenarios'!$E$2:$E$188,"Positive") -> 12 | D9: =COUNTIFS('Test Scenarios'!$A$2:$A$188,$A9,'Test Scenarios'!$E$2:$E$188,"Negative") -> 8 | E9: =COUNTIFS('Test Scenarios'!$A$2:$A$188,$A9,'Test Scenarios'!$M$2:$M$188,"File cũ") -> 5 | F9: =B9-E9 -> 15 | G9: =COUNTIFS('Test Scenarios'!$A$2:$A$188,$A9,'Test Scenarios'!$N$2:$N$188,"FAIL*") -> 6 | H9: =COUNTIFS('Test Scenarios'!$A$2:$A$188,$A9,'Test Scenarios'!$N$2:$N$188,"Cần xác nhận*") -> 0 | I9: =COUNTIFS('Test Scenarios'!$A$2:$A$188,$A9,'Test Scenarios'!$O$2:$O$188,"Lệch BA*") -> 3 | J9: =COUNTIFS('Test Scenarios'!$A$2:$A$188,$A9,'Test Scenarios'!$O$2:$O$188,"BA chưa quy định*") -> 3
A10: Admin Service | B10: =COUNTIF('Test Scenarios'!$A$2:$A$188,$A10) -> 20 | C10: =COUNTIFS('Test Scenarios'!$A$2:$A$188,$A10,'Test Scenarios'!$E$2:$E$188,"Positive") -> 15 | D10: =COUNTIFS('Test Scenarios'!$A$2:$A$188,$A10,'Test Scenarios'!$E$2:$E$188,"Negative") -> 5 | E10: =COUNTIFS('Test Scenarios'!$A$2:$A$188,$A10,'Test Scenarios'!$M$2:$M$188,"File cũ") -> 7 | F10: =B10-E10 -> 13 | G10: =COUNTIFS('Test Scenarios'!$A$2:$A$188,$A10,'Test Scenarios'!$N$2:$N$188,"FAIL*") -> 2 | H10: =COUNTIFS('Test Scenarios'!$A$2:$A$188,$A10,'Test Scenarios'!$N$2:$N$188,"Cần xác nhận*") -> 1 | I10: =COUNTIFS('Test Scenarios'!$A$2:$A$188,$A10,'Test Scenarios'!$O$2:$O$188,"Lệch BA*") -> 1 | J10: =COUNTIFS('Test Scenarios'!$A$2:$A$188,$A10,'Test Scenarios'!$O$2:$O$188,"BA chưa quy định*") -> 4
A11: API Gateway | B11: =COUNTIF('Test Scenarios'!$A$2:$A$188,$A11) -> 3 | C11: =COUNTIFS('Test Scenarios'!$A$2:$A$188,$A11,'Test Scenarios'!$E$2:$E$188,"Positive") -> 1 | D11: =COUNTIFS('Test Scenarios'!$A$2:$A$188,$A11,'Test Scenarios'!$E$2:$E$188,"Negative") -> 2 | E11: =COUNTIFS('Test Scenarios'!$A$2:$A$188,$A11,'Test Scenarios'!$M$2:$M$188,"File cũ") -> 0 | F11: =B11-E11 -> 3 | G11: =COUNTIFS('Test Scenarios'!$A$2:$A$188,$A11,'Test Scenarios'!$N$2:$N$188,"FAIL*") -> 2 | H11: =COUNTIFS('Test Scenarios'!$A$2:$A$188,$A11,'Test Scenarios'!$N$2:$N$188,"Cần xác nhận*") -> 0 | I11: =COUNTIFS('Test Scenarios'!$A$2:$A$188,$A11,'Test Scenarios'!$O$2:$O$188,"Lệch BA*") -> 0 | J11: =COUNTIFS('Test Scenarios'!$A$2:$A$188,$A11,'Test Scenarios'!$O$2:$O$188,"BA chưa quy định*") -> 2
A12: TỔNG CỘNG | B12: =SUM(B2:B11) -> 187 | C12: =SUM(C2:C11) -> 89 | D12: =SUM(D2:D11) -> 98 | E12: =SUM(E2:E11) -> 68 | F12: =SUM(F2:F11) -> 119 | G12: =SUM(G2:G11) -> 41 | H12: =SUM(H2:H11) -> 11 | I12: =SUM(I2:I11) -> 24 | J12: =SUM(J2:J11) -> 27
A14: Ghi chú
A15: 1. Căn cứ: tài liệu Phan-Tich-BA-CAB-System.docx (bản 1.2, 25 FR và 10 quy tắc nghiệp vụ có mã BR-1..10) - đúng bản mà bản triển khai (code) được xây dựng theo.
A16: 2. Mục tiêu: mỗi trong 9 service nghiệp vụ có 20 test case (68 test cũ cộng 112 test mới). Từ bản v17, thêm nhóm 'API Gateway' cho các test không thuộc riêng service nào (health check, và các gap hạ tầng khác theo bảng chấm thực hành) - nhóm này không theo mốc 20 test.
A17: 3. Cột 'Dự kiến khi chạy': PASS = dự kiến đạt. FAIL = dự kiến không đạt, cần sửa mã nguồn. Cần xác nhận = chưa đủ thông tin. Trong số này, 7 test (TC-DRV-19, TC-LOC-12, TC-PAY-18/19/20, TC-ADM-18, TC-PAY-12; cấu hình route hoặc model Payment) cùng giả thuyết ở ghi chú 10 chốt được bằng cách đọc mã, không cần chạy thử; các dòng còn lại cần chạy thật.
A18: 4. Cột 'Đối chiếu với BA': Đúng BA; BA chưa quy định (không phải lỗi, nhiều trường hợp đã liệt kê ở Mục 9 của BA là điểm chưa chốt); Lệch BA (vi phạm yêu cầu/quy tắc BA đã nêu, kèm trích dẫn); Chưa xác định (ứng với dòng Cần xác nhận). Khi nhiều test cùng dựa trên một hành vi đang chờ khách hàng quyết định (ví dụ bước thanh toán tiền mặt tự tạo, câu hỏi 8), mỗi test ghi rõ sự phụ thuộc này trong ngoặc, dù nhãn chính có thể khác nhau tùy góc kiểm.
A19: 5. Cột 'Quy tắc/NFR liên quan' dùng mã BR-1..9 (9 quy tắc nghiệp vụ, Mục 7) và NFR-1, NFR-2, NFR-3, NFR-4a, NFR-4b, NFR-5 (Mục 6) - từ bản BA 1.2, đây là MÃ CHÍNH THỨC của BA (trước đó là ký hiệu nội bộ do nhóm test tự đặt). Từ bản 1.2, mọi test đều có ít nhất một mã FR/BR/NFR ở cột 'FR liên quan', không còn dòng nào để '—'. Đối chiếu ở sheet 'Độ phủ FR'. Từ bản 1.3, chính sách hủy chuyến (câu hỏi 4) đã được khách hàng trả lời và đưa vào FR-24, BR-10 — không còn là đề xuất.
A20: 6. NFR Bảo mật tách hai phần: NFR-4a là phần đã chốt ở bản 1.0 (xác thực người dùng cuối, phân quyền quản trị); NFR-4b là đúng 16 test thuộc đề xuất bản 1.1 đang chờ khách hàng xác nhận (câu hỏi 7, Mục 9).
A21: 7. QUAN TRỌNG: bản 1.1 của BA có hai đề xuất đang chờ khách hàng xác nhận (Mục 9, câu hỏi 7 và 8): mở rộng NFR Bảo mật (16 test), và ai xác nhận thu tiền mặt (TC-PAY-01, TC-TRIP-15, TC-PAY-15, TC-NOTI-06 và bước 2 của TC-PAY-13 - 4 test và 1 bước). Chi tiết ở Nhat-Ky-Thay-Doi-BA-CAB-System.docx.
A22: 8. Cột 'Nguồn kịch bản' có mã TS-xxx là mã kịch bản lấy ý tưởng từ file Test-Scenario-CAB-System.xlsx (một bài tập phân tích BA mở rộng riêng, 62 FR, không phải căn cứ của bản triển khai) - chỉ để ghi nhận nguồn ý tưởng.
A23: 9. Độ phủ theo 23 FR, 9 quy tắc nghiệp vụ và 6 mục NFR (tách 4a/4b) của BA xem sheet 'Độ phủ FR'.
A24: 10. Chưa đưa vào 180 test: giả thuyết về độ bền sự kiện FareCalculated khi Payment Service dừng đúng lúc một chuyến khác hoàn thành (nếu bộ nhớ đệm cước chỉ nằm trong tiến trình và bus không lưu lại sự kiện, thanh toán sau khi Payment khởi động lại có thể báo FARE_NOT_AVAILABLE dù chuyến đã hoàn thành). Đây là giả thuyết chưa xác nhận từ mã nguồn, kiểm một thuộc tính khác (độ bền sự kiện) với TC-DISP-18 (cách ly lỗi), nên không gộp chung; cần một test riêng nếu xác nhận là vấn đề thật, hành vi đúng cần kiểm khi đó là: sau khi Payment khởi động lại, thanh toán chuyến vẫn thực hiện được hoặc trả về trạng thái có thể thử lại, không phải FARE_NOT_AVAILABLE. Xác nhận giả thuyết này chỉ cần đọc mã nguồn Payment Service để biết cước đang được lưu trong bộ nhớ tiến trình hay một nơi bền vững hơn, không cần chạy thử - xem ghi chú 3.
A25: 11. Ô 'Dự kiến khi chạy' tô đỏ đậm hơn (khác với FAIL tô đỏ nhạt thông thường) là FAIL đã được xác nhận bằng test Jest thật chạy trên hệ thống, không còn là dự đoán trên giấy — có ghi ngày và đường dẫn file test xác nhận. Tính đến 30/09/2026: 4/36 dòng FAIL đã xác nhận, đều thuộc Trip Service (TC-TRIP-14, 17, 18, 19). Các dòng FAIL còn lại vẫn là dự đoán, chờ chạy test thật ở các service khác.
... A38: 24. Chạy lại TC-CUST-21 và TC-GATE-01 (đã tách 3 test con) ngày 01/10/2026: TC-GATE-01 rõ hoàn toàn: 01a PASS (/health), 01b FAIL (/ready - 404), 01c FAIL (/health/services - 404) - cả /ready lẫn /health/services đều chưa được cài đặt ở Gateway, chỉ có /health hoạt động. TC-CUST-21 chưa có kết quả vì file chưa được copy vào tests/customer/ trên máy thật - cần chạy lại sau khi copy.

Sheet Độ phủ FR
A1: Độ phủ BA (bản 1.4) bởi 180 test case trong file này
A2: Số test tính bằng công thức: FR/BR/NFR từ cột 'FR liên quan', bổ sung từ cột 'Quy tắc/NFR liên quan' của sheet Test Scenarios. FR-25 và BR-10 là yêu cầu mới ở bản 1.3-1.4, hiện CHƯA có test case nào (scope mới, chưa triển khai ở bản code) — đây là khoảng trống thật, không phải thiếu sót khi gắn nhãn.
A4: Số FR có ít nhất 1 test | B4: =COUNTIF(C11:C36,">0") -> 24
A5: Số FR chưa có test | B5: =COUNTIF(C11:C36,0) -> 1
A6: Tổng số FR | B6: =B4+B5 -> 25
A7: Số quy tắc/NFR có ít nhất 1 test (trong 16 mục) | B7: =COUNTIF(C40:C58,">0") -> 13
A8: Số quy tắc/NFR chưa có test | B8: =COUNTIF(C40:C58,0) -> 3
A10: 1) 25 yêu cầu chức năng (FR) - Mục 5
A11: FR | B11: Nội dung | C11: Số test | D11: Trạng thái
A12: FR-01 | B12: Khách hàng đăng ký, đăng nhập, cập nhật thông tin cá nhân | C12: =SUMPRODUCT(--ISNUMBER(SEARCH(" "&$A12&",", " "&'Test Scenarios'!$C$2:$C$181&","))) + SUMPRODUCT(--ISNUMBER(SEARCH(" "&$A12&",", " "&'Test Scenarios'!$D$2:$D$181&","))) -> 15 | D12: =IF(C12=0,"Chưa có test","Có test") -> Có test
A13: FR-02 | B13: Tài xế đăng ký hoặc được nhân viên vận hành tạo tài khoản; cập nhật hồ sơ, thông tin phương tiện, trạng thái hoạt động | C13: =SUMPRODUCT(--ISNUMBER(SEARCH(" "&$A13&",", " "&'Test Scenarios'!$C$2:$C$181&","))) + SUMPRODUCT(--ISNUMBER(SEARCH(" "&$A13&",", " "&'Test Scenarios'!$D$2:$D$181&","))) -> 10 | D13: =IF(C13=0,"Chưa có test","Có test") -> Có test
A14: FR-03 | B14: Khách hàng nhập điểm đón/đến, chọn loại xe, gửi yêu cầu đặt xe | C14: =SUMPRODUCT(--ISNUMBER(SEARCH(" "&$A14&",", " "&'Test Scenarios'!$C$2:$C$181&","))) + SUMPRODUCT(--ISNUMBER(SEARCH(" "&$A14&",", " "&'Test Scenarios'!$D$2:$D$181&","))) -> 7 | D14: =IF(C14=0,"Chưa có test","Có test") -> Có test
A15: FR-04 | B15: Khách hàng theo dõi trạng thái chuyến theo thời gian thực | C15: =SUMPRODUCT(--ISNUMBER(SEARCH(" "&$A15&",", " "&'Test Scenarios'!$C$2:$C$181&","))) + SUMPRODUCT(--ISNUMBER(SEARCH(" "&$A15&",", " "&'Test Scenarios'!$D$2:$D$181&","))) -> 1 | D15: =IF(C15=0,"Chưa có test","Có test") -> Có test
A16: FR-05 | B16: Khách hàng xem lịch sử chuyến, số tiền phải trả, đánh giá tài xế sau khi hoàn thành | C16: =SUMPRODUCT(--ISNUMBER(SEARCH(" "&$A16&",", " "&'Test Scenarios'!$C$2:$C$181&","))) + SUMPRODUCT(--ISNUMBER(SEARCH(" "&$A16&",", " "&'Test Scenarios'!$D$2:$D$181&","))) -> 8 | D16: =IF(C16=0,"Chưa có test","Có test") -> Có test
A17: FR-06 | B17: Xác định tài xế phù hợp dựa trên vị trí, trạng thái sẵn sàng và tiêu chí vận hành | C17: =SUMPRODUCT(--ISNUMBER(SEARCH(" "&$A17&",", " "&'Test Scenarios'!$C$2:$C$181&","))) + SUMPRODUCT(--ISNUMBER(SEARCH(" "&$A17&",", " "&'Test Scenarios'!$D$2:$D$181&","))) -> 15 | D17: =IF(C17=0,"Chưa có test","Có test") -> Có test
A18: FR-07 | B18: Ưu tiên tài xế phù hợp và gần khách hàng nhất | C18: =SUMPRODUCT(--ISNUMBER(SEARCH(" "&$A18&",", " "&'Test Scenarios'!$C$2:$C$181&","))) + SUMPRODUCT(--ISNUMBER(SEARCH(" "&$A18&",", " "&'Test Scenarios'!$D$2:$D$181&","))) -> 4 | D18: =IF(C18=0,"Chưa có test","Có test") -> Có test
A19: FR-08 | B19: Tự động chuyển sang tài xế kế tiếp khi tài xế được đề xuất không phản hồi hoặc từ chối | C19: =SUMPRODUCT(--ISNUMBER(SEARCH(" "&$A19&",", " "&'Test Scenarios'!$C$2:$C$181&","))) + SUMPRODUCT(--ISNUMBER(SEARCH(" "&$A19&",", " "&'Test Scenarios'!$D$2:$D$181&","))) -> 7 | D19: =IF(C19=0,"Chưa có test","Có test") -> Có test
A20: FR-09 | B20: Thông báo rõ ràng cho khách hàng khi không tìm được tài xế phù hợp | C20: =SUMPRODUCT(--ISNUMBER(SEARCH(" "&$A20&",", " "&'Test Scenarios'!$C$2:$C$181&","))) + SUMPRODUCT(--ISNUMBER(SEARCH(" "&$A20&",", " "&'Test Scenarios'!$D$2:$D$181&","))) -> 2 | D20: =IF(C20=0,"Chưa có test","Có test") -> Có test
A21: FR-10 | B21: Ghi nhận và cập nhật vị trí tài xế theo thời gian thực | C21: =SUMPRODUCT(--ISNUMBER(SEARCH(" "&$A21&",", " "&'Test Scenarios'!$C$2:$C$181&","))) + SUMPRODUCT(--ISNUMBER(SEARCH(" "&$A21&",", " "&'Test Scenarios'!$D$2:$D$181&","))) -> 11 | D21: =IF(C21=0,"Chưa có test","Có test") -> Có test
A22: FR-11 | B22: Tài xế chuyển trạng thái sẵn sàng nhận chuyến khi đang làm việc | C22: =SUMPRODUCT(--ISNUMBER(SEARCH(" "&$A22&",", " "&'Test Scenarios'!$C$2:$C$181&","))) + SUMPRODUCT(--ISNUMBER(SEARCH(" "&$A22&",", " "&'Test Scenarios'!$D$2:$D$181&","))) -> 4 | D22: =IF(C22=0,"Chưa có test","Có test") -> Có test
A23: FR-12 | B23: Tài xế nhận thông báo chuyến phù hợp và chấp nhận/từ chối | C23: =SUMPRODUCT(--ISNUMBER(SEARCH(" "&$A23&",", " "&'Test Scenarios'!$C$2:$C$181&","))) + SUMPRODUCT(--ISNUMBER(SEARCH(" "&$A23&",", " "&'Test Scenarios'!$D$2:$D$181&","))) -> 6 | D23: =IF(C23=0,"Chưa có test","Có test") -> Có test
... A36: FR-24 | B36: Khách hàng hủy yêu cầu đặt xe hoặc chuyến đi khi chưa đón khách (trước trạng thái picked_up) | C36: =SUMPRODUCT(--ISNUMBER(SEARCH(" "&$A36&",", " "&'Test Scenarios'!$C$2:$C$181&","))) + SUMPRODUCT(--ISNUMBER(SEARCH(" "&$A36&",", " "&'Test Scenarios'!$D$2:$D$181&","))) -> 3 | D36: =IF(C36=0,"Chưa có test","Có test") -> Có test
A38: 2) 10 quy tắc nghiệp vụ (Mục 7) - mã BR-1..10
A39: BR | B39: Nội dung | C39: Số test | D39: Trạng thái
A40: BR-1 | B40: Tài xế chỉ nhận yêu cầu ghép chuyến khi đang ở trạng thái sẵn sàng nhận chuyến | C40: =SUMPRODUCT(--ISNUMBER(SEARCH(" "&$A40&",", " "&'Test Scenarios'!$C$2:$C$181&","))) + SUMPRODUCT(--ISNUMBER(SEARCH(" "&$A40&",", " "&'Test Scenarios'!$D$2:$D$181&","))) -> 3 | D40: =IF(C40=0,"Chưa có test","Có test") -> Có test
A41: BR-2 | B41: Ưu tiên tài xế dựa trên mức độ phù hợp và khoảng cách gần khách hàng | C41: =SUMPRODUCT(--ISNUMBER(SEARCH(" "&$A41&",", " "&'Test Scenarios'!$C$2:$C$181&","))) + SUMPRODUCT(--ISNUMBER(SEARCH(" "&$A41&",", " "&'Test Scenarios'!$D$2:$D$181&","))) -> 3 | D41: =IF(C41=0,"Chưa có test","Có test") -> Có test
A42: BR-3 | B42: Không phản hồi/từ chối thì tự động chuyển tài xế kế tiếp, không cần khách tạo lại yêu cầu | C42: =SUMPRODUCT(--ISNUMBER(SEARCH(" "&$A42&",", " "&'Test Scenarios'!$C$2:$C$181&","))) + SUMPRODUCT(--ISNUMBER(SEARCH(" "&$A42&",", " "&'Test Scenarios'!$D$2:$D$181&","))) -> 3 | D42: =IF(C42=0,"Chưa có test","Có test") -> Có test
A43: BR-4 | B43: Không tìm được tài xế phù hợp thì khách phải được thông báo rõ ràng | C43: =SUMPRODUCT(--ISNUMBER(SEARCH(" "&$A43&",", " "&'Test Scenarios'!$C$2:$C$181&","))) + SUMPRODUCT(--ISNUMBER(SEARCH(" "&$A43&",", " "&'Test Scenarios'!$D$2:$D$181&","))) -> 1 | D43: =IF(C43=0,"Chưa có test","Có test") -> Có test
A44: BR-5 | B44: Cước phí chỉ được tính sau khi chuyến đi hoàn thành | C44: =SUMPRODUCT(--ISNUMBER(SEARCH(" "&$A44&",", " "&'Test Scenarios'!$C$2:$C$181&","))) + SUMPRODUCT(--ISNUMBER(SEARCH(" "&$A44&",", " "&'Test Scenarios'!$D$2:$D$181&","))) -> 2 | D44: =IF(C44=0,"Chưa có test","Có test") -> Có test
A45: BR-6 | B45: Thông tin thẻ/tài khoản thanh toán nhạy cảm không lưu trực tiếp, xử lý qua đối tác ngoài | C45: =SUMPRODUCT(--ISNUMBER(SEARCH(" "&$A45&",", " "&'Test Scenarios'!$C$2:$C$181&","))) + SUMPRODUCT(--ISNUMBER(SEARCH(" "&$A45&",", " "&'Test Scenarios'!$D$2:$D$181&","))) -> 1 | D45: =IF(C45=0,"Chưa có test","Có test") -> Có test
A46: BR-7 | B46: Giao dịch điện tử thất bại phải thông báo khách hàng và có thể xử lý lại | C46: =SUMPRODUCT(--ISNUMBER(SEARCH(" "&$A46&",", " "&'Test Scenarios'!$C$2:$C$181&","))) + SUMPRODUCT(--ISNUMBER(SEARCH(" "&$A46&",", " "&'Test Scenarios'!$D$2:$D$181&","))) -> 1 | D46: =IF(C46=0,"Chưa có test","Có test") -> Có test
A47: BR-8 | B47: Một số chức năng quản trị chỉ dành cho nhân viên được phân quyền | C47: =SUMPRODUCT(--ISNUMBER(SEARCH(" "&$A47&",", " "&'Test Scenarios'!$C$2:$C$181&","))) + SUMPRODUCT(--ISNUMBER(SEARCH(" "&$A47&",", " "&'Test Scenarios'!$D$2:$D$181&","))) -> 11 | D47: =IF(C47=0,"Chưa có test","Có test") -> Có test
A48: BR-9 | B48: Mọi thao tác quan trọng phải được lưu vết (audit log) | C48: =SUMPRODUCT(--ISNUMBER(SEARCH(" "&$A48&",", " "&'Test Scenarios'!$C$2:$C$181&","))) + SUMPRODUCT(--ISNUMBER(SEARCH(" "&$A48&",", " "&'Test Scenarios'!$D$2:$D$181&","))) -> 0 | D48: =IF(C48=0,"Chưa có test","Có test") -> Chưa có test
A49: BR-10 | B49: Chuyến kết thúc sớm hơn dự kiến vẫn tính đủ cước theo cước ước tính lúc đặt xe (FR-25) | C49: =SUMPRODUCT(--ISNUMBER(SEARCH(" "&$A49&",", " "&'Test Scenarios'!$C$2:$C$181&","))) + SUMPRODUCT(--ISNUMBER(SEARCH(" "&$A49&",", " "&'Test Scenarios'!$D$2:$D$181&","))) -> 0 | D49: =IF(C49=0,"Chưa có test","Có test") -> Chưa có test
A51: 3) NFR (Mục 6) - mã NFR-1, NFR-2, NFR-3, NFR-4a, NFR-4b, NFR-5
A52: NFR | B52: Nội dung | C52: Số test | D52: Trạng thái
A53: NFR-1 | B53: Tính sẵn sàng / Ổn định - lỗi thanh toán hoặc thông báo không được làm hệ thống đặt xe ngừng hoạt động | C53: =SUMPRODUCT(--ISNUMBER(SEARCH(" "&$A53&",", " "&'Test Scenarios'!$C$2:$C$181&","))) + SUMPRODUCT(--ISNUMBER(SEARCH(" "&$A53&",", " "&'Test Scenarios'!$D$2:$D$181&","))) -> 2 | D53: =IF(C53=0,"Chưa có test","Có test") -> Có test
A54: NFR-2 | B54: Khả năng mở rộng (Scalability) | C54: =SUMPRODUCT(--ISNUMBER(SEARCH(" "&$A54&",", " "&'Test Scenarios'!$C$2:$C$181&","))) + SUMPRODUCT(--ISNUMBER(SEARCH(" "&$A54&",", " "&'Test Scenarios'!$D$2:$D$181&","))) -> 0 | D54: =IF(C54=0,"Chưa có test","Có test") -> Chưa có test
A55: NFR-3 | B55: Khả năng triển khai (Deployability) | C55: =SUMPRODUCT(--ISNUMBER(SEARCH(" "&$A55&",", " "&'Test Scenarios'!$C$2:$C$181&","))) + SUMPRODUCT(--ISNUMBER(SEARCH(" "&$A55&",", " "&'Test Scenarios'!$D$2:$D$181&","))) -> 1 | D55: =IF(C55=0,"Chưa có test","Có test") -> Có test
A56: NFR-4a | B56: Bảo mật (Security) - đã chốt ở bản 1.0 | C56: =SUMPRODUCT(--ISNUMBER(SEARCH(" "&$A56&",", " "&'Test Scenarios'!$C$2:$C$181&","))) + SUMPRODUCT(--ISNUMBER(SEARCH(" "&$A56&",", " "&'Test Scenarios'!$D$2:$D$181&","))) -> 31 | D56: =IF(C56=0,"Chưa có test","Có test") -> Có test
...
